Workbook

Sheet Valoración Usabilidad
A1: Usability review (Español) | Q1: Enter score | R1: 0
Q2: Very poor | R2: 1
A3: [Enter product name] | D3: Score | I3: Comments | Q3: Poor | R3: 2
Q4: Moderate | R4: 3
B5: Hover over a guideline for more information, examples of good practice and importance to the overall user experience. | D5: N/A = not applicable or can't be assessed | I5: Optional - Provide a short rational for the score, such as a description of the issues found; examples of good practice and the likely impact for users. | Q5: Good | R5: 4
Q6: Excellent | R6: 5
A7: Features & functionality | K7: Weighting (out of 5) | L7: Weighting ratio | M7: Rating (0 - 5) | N7: Score | O7: Out of | Q7: N/A | R7: 0
A9: 1 | B9: Las características y la funcionalidad cumplen con las metas y objetivos comunes del usuario. | D9: Poor | F9: =#REF!*#REF! -> #REF! | G9: =IF(#REF!>=0,10*#REF!,0) -> #REF! | I9: El principal objetivo que tendrá un usuario será ver la carta o reservar mesa, la opción de reservar mesa si está bastante visible y accesible, sin embargo, el usuario debe navegar demasiado dentro de la web para llegar a la seccion de la carta. El menu desplegable de hamburguesa no es intuitivo y no da "feedback" cuando interactuas con el | K9: 5 | L9: =K9/K117 -> 1 | M9: =VLOOKUP(D9,Q1:R9,2,FALSE) -> 2 | N9: =M9*L9 -> 2 | O9: =IF(M9=0,0,L9*MAX(R2:R8)) -> 5
A11: =A9+1 -> 2 | B11: Las características y la funcionalidad son compatibles con los flujos de trabajo deseados por los usuarios. | D11: Poor | F11: =#REF!*#REF! -> #REF! | G11: =IF(#REF!>=0,10*#REF!,0) -> #REF! | I11: Como se menciona en el apartado anterior, el usuario, para acceder a la carta, tiene que avanzar demasiado dentro de la web lo que puede hacer que el usuario se pierda con tanta información. | K11: 5 | L11: =K11/K117 -> 1 | M11: =VLOOKUP(D11,Q1:R9,2,FALSE) -> 2 | N11: =M11*L11 -> 2 | O11: =IF(M11=0,0,L11*MAX(R2:R8)) -> 5
A13: =A11+1 -> 3 | B13: Las tareas de uso frecuente están fácilmente disponibles (por ejemplo, fácilmente accesibles desde la página de inicio) y están bien soportadas (por ejemplo, los accesos directos están disponibles). | D13: Poor | F13: =#REF!*#REF! -> #REF! | G13: =IF(#REF!>=0,10*#REF!,0) -> #REF! | I13: Los accesos a las distintas secciones de la web funcionan, sin embargo, no resultan nada vistosos ni dan informacion cuando se interactua, por otro lado es común colocar el menú desplegable en la zona superior derecha, en esta web el menú está colocado en la zona superior izquierda por lo cual no es lo estandar. El logo no funciona a la hora de volver a la página principal | K13: 4 | L13: =K13/K117 -> 0.8 | M13: =VLOOKUP(D13,Q1:R9,2,FALSE) -> 2 | N13: =M13*L13 -> 1.6 | O13: =IF(M13=0,0,L13*MAX(R2:R8)) -> 4
A15: =A13+1 -> 4 | B15: Los usuarios reciben un apoyo adecuado según su nivel de experiencia (por ejemplo, atajos para usuarios expertos, ayuda e instrucciones para usuarios novatos). | D15: Very poor | F15: =#REF!*#REF! -> #REF! | G15: =IF(#REF!>=0,10*#REF!,0) -> #REF! | I15: No está implementada de manera correcta la navegación por teclado por lo que no permitirá el correcto funcionamiento de los lectores de pantalla que usan las personas ciegas. | K15: 3 | L15: =K15/K117 -> 0.6 | M15: =VLOOKUP(D15,Q1:R9,2,FALSE) -> 1 | N15: =M15*L15 -> 0.6 | O15: =IF(M15=0,0,L15*MAX(R2:R8)) -> 3
A17: =A15+1 -> 5 | B17: Las llamadas a las acciones (por ejemplo, registrarse, agregar a la cesta, enviar) son claras, están bien etiquetadas y aparecen como cliqueables. | D17: Good | F17: =#REF!*#REF! -> #REF! | G17: =IF(#REF!>=0,10*#REF!,0) -> #REF! | I17: Las secciones se encuentran dentro de la cabecera por lo que hacen que el usuario se fije en ellas rápidamente. | K17: 3 | L17: =K17/K117 -> 0.6 | M17: =VLOOKUP(D17,Q1:R9,2,FALSE) -> 4 | N17: =M17*L17 -> 2.4 | O17: =IF(M17=0,0,L17*MAX(R2:R8)) -> 3
A19: Homepage / starting page
A21: =A17+1 -> 6 | B21: La página de inicio proporciona una instantánea clara y una descripción general del contenido, las características y la funcionalidad disponible. | D21: Moderate | F21: =#REF!*#REF! -> #REF! | G21: =IF(#REF!>=0,10*#REF!,0) -> #REF! | I21: La página de inicio tiene un patron en Z colocando en la parte de la cabecera cosas importantes como reservar mesa o hacer pedido. Sin embargo se podría colocar la carta un par de secciones antes debido a la importancia de esta. | K21: 3 | L21: =K21/K117 -> 0.6 | M21: =VLOOKUP(D21,Q1:R9,2,FALSE) -> 3 | N21: =M21*L21 -> 1.8 | O21: =IF(M21=0,0,L21*MAX(R2:R8)) -> 3
A23: =A21+1 -> 7 | B23: La página de inicio es eficaz para orientar y dirigir a los usuarios a la información y las tareas deseadas. | D23: Poor | F23: =#REF!*#REF! -> #REF! | G23: =IF(#REF!>=0,10*#REF!,0) -> #REF! | I23: La distribución de las secciones de la web deja bastante que desear porque no sigue ninguna estructura lo que puede hacer que el usuario se pierda. | K23: 4 | L23: =K23/K117 -> 0.8 | M23: =VLOOKUP(D23,Q1:R9,2,FALSE) -> 2 | N23: =M23*L23 -> 1.6 | O23: =IF(M23=0,0,L23*MAX(R2:R8)) -> 4
A25: =A23+1 -> 8 | B25: El diseño de la página de inicio es clara y ordenada con suficiente "espacio en blanco". | D25: Moderate | I25: La web tiene demasiada información con la finalidad de que compres X producto aunque está distribuida de una forma que, pese a tener muchas secciones, estas no están muy sobrecargadas. | K25: 3 | L25: =K25/K117 -> 0.6 | M25: =VLOOKUP(D25,Q1:R9,2,FALSE) -> 3 | N25: =M25*L25 -> 1.8 | O25: =IF(M25=0,0,L25*MAX(R2:R8)) -> 3
A27: Navigation
A29: =A25+1 -> 9 | B29: Los usuarios pueden acceder fácilmente al sitio o la aplicación (por ejemplo, la URL es predecible y es devuelta por los motores de búsqueda). | D29: Good | F29: =#REF!*#REF! -> #REF! | G29: =IF(#REF!>=0,10*#REF!,0) -> #REF! | I29: La navegación dentro de la web está mostrada en la URL lo que puede hacer que el usuario más experimentado sepa la sección en la que se encuentra | K29: 2 | L29: =K29/K117 -> 0.4 | M29: =VLOOKUP(D29,Q1:R9,2,FALSE) -> 4 | N29: =M29*L29 -> 1.6 | O29: =IF(M29=0,0,L29*MAX(R2:R8)) -> 2
A31: =A29+1 -> 10 | B31: El esquema de navegación (por ejemplo, el menú) es fácil de encontrar, intuitivo y consistente. | D31: Poor | F31: =#REF!*#REF! -> #REF! | G31: =IF(#REF!>=0,10*#REF!,0) -> #REF! | I31: Encontramos un menú de hamburguesa desplegable, que una vez abierto, hace que no sea posible de nuevo la navegación dentro de la web ya que ocupa toda la pantalla. Este menú no tiene interacción con el usuario al pasar el cursor. | K31: 4 | L31: =K31/K117 -> 0.8 | M31: =VLOOKUP(D31,Q1:R9,2,FALSE) -> 2 | N31: =M31*L31 -> 1.6 | O31: =IF(M31=0,0,L31*MAX(R2:R8)) -> 4
A33: =A31+1 -> 11 | B33: La navegación tiene la flexibilidad suficiente para permitir que los usuarios naveguen por los medios deseados (por ejemplo, búsqueda, navegación por tipo, navegación por nombre, más reciente, etc.). | D33: Very poor | I33: No se encuentra eso dentro de la web, la carta del restaurante tiene todas sus secciones mezcladas, esto puede dar lugar a confusión. | K33: 3 | L33: =K33/K117 -> 0.6 | M33: =VLOOKUP(D33,Q1:R9,2,FALSE) -> 1 | N33: =M33*L33 -> 0.6 | O33: =IF(M33=0,0,L33*MAX(R2:R8)) -> 3
A35: =A33+1 -> 12 | B35: La estructura del sitio o la aplicación es clara, fácil de entender y aborda objetivos comunes del usuario. | D35: Very poor | F35: =#REF!*#REF! -> #REF! | G35: =IF(#REF!>=0,10*#REF!,0) -> #REF! | I35: La web es un lío, la función principal que ha buscado el diseñador es que el usuario haga scroll para que se vaya encontrando las distintas secciones de la web. Que en teoría debería de ser funcional al buscar ser usado por usuario de móviles, sin embargo la implementación no es correcta. | K35: 5 | L35: =K35/K117 -> 1 | M35: =VLOOKUP(D35,Q1:R9,2,FALSE) -> 1 | N35: =M35*L35 -> 1 | O35: =IF(M35=0,0,L35*MAX(R2:R8)) -> 5
A37: =A35+1 -> 13 | B37: Los enlaces son claros, descriptivos y están bien etiquetados. | D37: Poor | F37: =#REF!*#REF! -> #REF! | G37: =IF(#REF!>=0,10*#REF!,0) -> #REF! | I37: Los botones con enlaces no poseen ninguna etiqueta cuando colocas el cursor encima, lo cual no proporciona toda la información que debería proporcionar. | K37: 3 | L37: =K37/K117 -> 0.6 | M37: =VLOOKUP(D37,Q1:R9,2,FALSE) -> 2 | N37: =M37*L37 -> 1.2 | O37: =IF(M37=0,0,L37*MAX(R2:R8)) -> 3
A39: =A37+1 -> 14 | B39: Las funciones estándar del navegador (por ejemplo, 'atrás', 'adelante', 'marcador') son compatibles. | D39: Moderate | F39: =#REF!*#REF! -> #REF! | G39: =IF(#REF!>=0,10*#REF!,0) -> #REF! | I39: Se puede navegar 'atrás' y 'adelante' sin embargo si entras en la sección de hacer pedido, y quieres volver atrás a la página principal, lo establecido es que el propio logo de la web sea un botón que devuelve a la página principal, en este caso no funciona. | K39: 4 | L39: =K39/K117 -> 0.8 | M39: =VLOOKUP(D39,Q1:R9,2,FALSE) -> 3 | N39: =M39*L39 -> 2.4 | O39: =IF(M39=0,0,L39*MAX(R2:R8)) -> 4
A41: =A39+1 -> 15 | B41: La ubicación actual está claramente indicada (por ejemplo, ruta de navegación, elemento de menú resaltado). | D41: Good | F41: =#REF!*#REF! -> #REF! | G41: =IF(#REF!>=0,10*#REF!,0) -> #REF! | I41: Los botones están claramente marcados destacando el boton 'reservar' . | K41: 2 | L41: =K41/K117 -> 0.4 | M41: =VLOOKUP(D41,Q1:R9,2,FALSE) -> 4 | N41: =M41*L41 -> 1.6 | O41: =IF(M41=0,0,L41*MAX(R2:R8)) -> 2
A43: =A41+1 -> 16 | B43: Los usuarios pueden volver fácilmente a la página de inicio o a un punto de inicio relevante. | D43: Very poor | F43: =#REF!*#REF! -> #REF! | G43: =IF(#REF!>=0,10*#REF!,0) -> #REF! | I43: Como hemos dicho en el punto 14 el logo no funciona como botón para volver a la página principal, hay que borrar la url para poder volver. | K43: 2 | L43: =K43/K117 -> 0.4 | M43: =VLOOKUP(D43,Q1:R9,2,FALSE) -> 1 | N43: =M43*L43 -> 0.4 | O43: =IF(M43=0,0,L43*MAX(R2:R8)) -> 2
A45: =A43+1 -> 17 | B45: Se proporciona un mapa del sitio o índice claro y bien estructurado (cuando sea necesario) | D45: Very poor | F45: =#REF!*#REF! -> #REF! | G45: =IF(#REF!>=0,10*#REF!,0) -> #REF! | I45: Al navegar a la sección de 'hacer pedido' no sale un mapa para saber a qué restaurante estás haciendo el pedido y la distancia a la que se encuentra. | K45: 1 | L45: =K45/K117 -> 0.2 | M45: =VLOOKUP(D45,Q1:R9,2,FALSE) -> 1 | N45: =M45*L45 -> 0.2 | O45: =IF(M45=0,0,L45*MAX(R2:R8)) -> 1
A47: Search
A49: =A45+1 -> 18 | B49: Una función de búsqueda consistente, fácil de encontrar y fácil de usar está disponible en todas partes (cuando sea conveniente) | D49: Moderate | F49: =#REF!*#REF! -> #REF! | G49: =IF(#REF!>=0,10*#REF!,0) -> #REF! | I49: La organización de la web está constante en toda navegación, sin embargo, esta organización puede ser bastante liosa. | K49: 4 | L49: =K49/K117 -> 0.8 | M49: =VLOOKUP(D49,Q1:R9,2,FALSE) -> 3 | N49: =M49*L49 -> 2.4 | O49: =IF(M49=0,0,L49*MAX(R2:R8)) -> 4
A51: =A49+1 -> 19 | B51: La interfaz de búsqueda es adecuada para cumplir los objetivos del usuario (por ejemplo, parámetros múltiples, resultados priorizados, filtrado de resultados de búsqueda) | D51: Moderate | F51: =#REF!*#REF! -> #REF! | G51: =IF(#REF!>=0,10*#REF!,0) -> #REF! | I51: La web está diseñada para vender los productos más destacados de la franquicia, sin embargo, no aporta filtrado de búsqueda dentro de la carta. | K51: 4 | L51: =K51/K117 -> 0.8 | M51: =VLOOKUP(D51,Q1:R9,2,FALSE) -> 3 | N51: =M51*L51 -> 2.4 | O51: =IF(M51=0,0,L51*MAX(R2:R8)) -> 4
A53: =A51+1 -> 20 | B53: El servicio de búsqueda se ocupa de las búsquedas comunes (por ejemplo, muestra la mayoría de resultados populares), faltas de ortografía y abreviaturas. | D53: Very poor | F53: =#REF!*#REF! -> #REF! | G53: =IF(#REF!>=0,10*#REF!,0) -> #REF! | I53: No se ofrece dicha caracteristica | K53: 2 | L53: =K53/K117 -> 0.4 | M53: =VLOOKUP(D53,Q1:R9,2,FALSE) -> 1 | N53: =M53*L53 -> 0.4 | O53: =IF(M53=0,0,L53*MAX(R2:R8)) -> 2
A55: =A53+1 -> 21 | B55: Los resultados de búsqueda son relevantes, exhaustivos, precisos y se muestran bien | D55: N/A | F55: =#REF!*#REF! -> #REF! | G55: =IF(#REF!>=0,10*#REF!,0) -> #REF! | K55: 4 | L55: =K55/K117 -> 0.8 | M55: =VLOOKUP(D55,Q1:R9,2,FALSE) -> 0 | N55: =M55*L55 -> 0 | O55: =IF(M55=0,0,L55*MAX(R2:R8)) -> 0
A57: Control & feedback
A59: =A55+1 -> 22 | B59: Se proporciona una respuesta rápida y apropiada (por ejemplo, después de una acción exitosa o no exitosa). | D59: Excellent | F59: =#REF!*#REF! -> #REF! | G59: =IF(#REF!>=0,10*#REF!,0) -> #REF! | I59: La navegación dentro de la web ofrece respuestas rapidas y rapidas | K59: 4 | L59: =K59/K117 -> 0.8 | M59: =VLOOKUP(D59,Q1:R9,2,FALSE) -> 5 | N59: =M59*L59 -> 4 | O59: =IF(M59=0,0,L59*MAX(R2:R8)) -> 4
A61: =A59+1 -> 23 | B61: Los usuarios pueden fácilmente deshacer, volver atrás y cambiar o cancelar acciones; o al menos tienen la oportunidad de confirmar una acción antes de cometer (por ejemplo, antes de realizar un pedido) | D61: Good | F61: =#REF!*#REF! -> #REF! | G61: =IF(#REF!>=0,10*#REF!,0) -> #REF! | I61: En la sección de recoger un pedido, una vez seleccionado la opción "programar mi pedido" , no se puede volver a marcar la opción "lo antes posible" si no se reinicia la página. En cuanto a las reservas, si queremos modificar una reserva podemos darle al botón de volver y los datos insertados se guardan | K61: 3 | L61: =K61/K117 -> 0.6 | M61: =VLOOKUP(D61,Q1:R9,2,FALSE) -> 4 | N61: =M61*L61 -> 2.4 | O61: =IF(M61=0,0,L61*MAX(R2:R8)) -> 3
A63: =A61+1 -> 24 | B63: Los usuarios pueden enviar comentarios (por ejemplo, por correo electrónico o mediante un formulario de comentarios / contacto en línea) | D63: Poor | F63: =#REF!*#REF! -> #REF! | G63: =IF(#REF!>=0,10*#REF!,0) -> #REF! | I63: Hay una sección de contacto llamada "atención al cliente" pero está situado en la parte inferior de la página en un lugar donde no destaca | K63: 1 | L63: =K63/K117 -> 0.2 | M63: =VLOOKUP(D63,Q1:R9,2,FALSE) -> 2 | N63: =M63*L63 -> 0.4 | O63: =IF(M63=0,0,L63*MAX(R2:R8)) -> 1
A65: Forms
A67: =A63+1 -> 25 | B67: Los formularios y los procesos complejos se dividen en pasos y secciones fácilmente comprensibles. Cuando se utiliza un proceso, hay un indicador de progreso con números claros o etapas con nombre. | D67: Very poor | F67: =#REF!*#REF! -> #REF! | G67: =IF(#REF!>=0,10*#REF!,0) -> #REF! | I67: No hay ningún indicador de progreso a la hora de pedir un producto, de hecho el a la hora de elegir el producto a pedir, se avanza a la siguiente sección con el botón "finalizar pedido" lo que puede llevar a confusión | K67: 3 | L67: =K67/K117 -> 0.6 | M67: =VLOOKUP(D67,Q1:R9,2,FALSE) -> 1 | N67: =M67*L67 -> 0.6 | O67: =IF(M67=0,0,L67*MAX(R2:R8)) -> 3
A69: =A67+1 -> 26 | B69: Se solicita una cantidad mínima de información y, cuando se proporciona la justificación necesaria para solicitar información (por ejemplo, fecha de nacimiento, número de teléfono) | D69: Good | F69: =#REF!*#REF! -> #REF! | G69: =IF(#REF!>=0,10*#REF!,0) -> #REF! | I69: Se necesita dar información muy básica, a excepción de un apartado de comentarios acecrca del pedido | K69: 2 | L69: =K69/K117 -> 0.4 | M69: =VLOOKUP(D69,Q1:R9,2,FALSE) -> 4 | N69: =M69*L69 -> 1.6 | O69: =IF(M69=0,0,L69*MAX(R2:R8)) -> 2
A71: =A69+1 -> 27 | B71: Los campos de formulario requeridos y opcionales están claramente indicados | D71: Very poor | F71: =#REF!*#REF! -> #REF! | G71: =IF(#REF!>=0,10*#REF!,0) -> #REF! | I71: No se diferencia entre campos opcionales y obligatorios | K71: 2 | L71: =K71/K117 -> 0.4 | M71: =VLOOKUP(D71,Q1:R9,2,FALSE) -> 1 | N71: =M71*L71 -> 0.4 | O71: =IF(M71=0,0,L71*MAX(R2:R8)) -> 2
A73: =A71+1 -> 28 | B73: Se utilizan los campos de entrada apropiados (por ejemplo, el calendario para la selección de la fecha, el menú desplegable para la selección) y se indican los formatos requeridos | D73: Moderate | F73: =#REF!*#REF! -> #REF! | G73: =IF(#REF!>=0,10*#REF!,0) -> #REF! | I73: A la hora de reservar, la fecha está implementada con un sistema de calendario, sin embargo, la hora está implementado con un sistema de menú donde es más tedioso encontrar tu hora | K73: 3 | L73: =K73/K117 -> 0.6 | M73: =VLOOKUP(D73,Q1:R9,2,FALSE) -> 3 | N73: =M73*L73 -> 1.8 | O73: =IF(M73=0,0,L73*MAX(R2:R8)) -> 3
...

Sheet Usability scores
A1: Usability review | Q1: Enter score | R1: 0
Q2: Very poor | R2: 1
A3: [Enter product name] | D3: Score | I3: Comments | Q3: Poor | R3: 2
Q4: Moderate | R4: 3
B5: Hover over a guideline for more information, examples of good practice and importance to the overall user experience. | D5: N/A = not applicable or can't be assessed | I5: Optional - Provide a short rational for the score, such as a description of the issues found; examples of good practice and the likely impact for users. | Q5: Good | R5: 4
Q6: Excellent | R6: 5
A7: Features & functionality | K7: Weighting (out of 5) | L7: Weighting ratio | M7: Rating (0 - 5) | N7: Score | O7: Out of | Q7: N/A | R7: 0
A9: 1 | B9: Features and functionality meet common user goals and objectives. | D9: Enter score | F9: =#REF!*#REF! -> #REF! | G9: =IF(#REF!>=0,10*#REF!,0) -> #REF! | K9: 5 | L9: =K9/K117 -> 1 | M9: =VLOOKUP(D9,Q1:R9,2,FALSE) -> 0 | N9: =M9*L9 -> 0 | O9: =IF(M9=0,0,L9*MAX(R2:R8)) -> 0
A11: =A9+1 -> 2 | B11: Features and functionality support users desired workflows. | D11: Enter score | F11: =#REF!*#REF! -> #REF! | G11: =IF(#REF!>=0,10*#REF!,0) -> #REF! | K11: 5 | L11: =K11/K117 -> 1 | M11: =VLOOKUP(D11,Q1:R9,2,FALSE) -> 0 | N11: =M11*L11 -> 0 | O11: =IF(M11=0,0,L11*MAX(R2:R8)) -> 0
A13: =A11+1 -> 3 | B13: Frequently-used tasks are readily available (e.g. easily accessible from the homepage) and well supported (e.g. short cuts are available). | D13: Enter score | F13: =#REF!*#REF! -> #REF! | G13: =IF(#REF!>=0,10*#REF!,0) -> #REF! | K13: 4 | L13: =K13/K117 -> 0.8 | M13: =VLOOKUP(D13,Q1:R9,2,FALSE) -> 0 | N13: =M13*L13 -> 0 | O13: =IF(M13=0,0,L13*MAX(R2:R8)) -> 0
A15: =A13+1 -> 4 | B15: Users are adequately supported according to their level of expertise (e.g. short cuts for expert users, help and instructions for novice users). | D15: Enter score | F15: =#REF!*#REF! -> #REF! | G15: =IF(#REF!>=0,10*#REF!,0) -> #REF! | K15: 3 | L15: =K15/K117 -> 0.6 | M15: =VLOOKUP(D15,Q1:R9,2,FALSE) -> 0 | N15: =M15*L15 -> 0 | O15: =IF(M15=0,0,L15*MAX(R2:R8)) -> 0
A17: =A15+1 -> 5 | B17: Call to actions (e.g. register, add to basket, submit) are clear, well labelled and appear clickable. | D17: Enter score | F17: =#REF!*#REF! -> #REF! | G17: =IF(#REF!>=0,10*#REF!,0) -> #REF! | K17: 3 | L17: =K17/K117 -> 0.6 | M17: =VLOOKUP(D17,Q1:R9,2,FALSE) -> 0 | N17: =M17*L17 -> 0 | O17: =IF(M17=0,0,L17*MAX(R2:R8)) -> 0
A19: Homepage / starting page
A21: =A17+1 -> 6 | B21: The Homepage / starting page provides a clear snapshot and overview of the content, features and functionality available. | D21: Enter score | F21: =#REF!*#REF! -> #REF! | G21: =IF(#REF!>=0,10*#REF!,0) -> #REF! | K21: 3 | L21: =K21/K117 -> 0.6 | M21: =VLOOKUP(D21,Q1:R9,2,FALSE) -> 0 | N21: =M21*L21 -> 0 | O21: =IF(M21=0,0,L21*MAX(R2:R8)) -> 0
A23: =A21+1 -> 7 | B23: The home page / starting page is effective in orienting and directing users to their desired information and tasks. | D23: Enter score | F23: =#REF!*#REF! -> #REF! | G23: =IF(#REF!>=0,10*#REF!,0) -> #REF! | K23: 4 | L23: =K23/K117 -> 0.8 | M23: =VLOOKUP(D23,Q1:R9,2,FALSE) -> 0 | N23: =M23*L23 -> 0 | O23: =IF(M23=0,0,L23*MAX(R2:R8)) -> 0
A25: =A23+1 -> 8 | B25: The homepage / starting page layout is clear and uncluttered with sufficient 'white space'. | D25: Enter score | K25: 3 | L25: =K25/K117 -> 0.6 | M25: =VLOOKUP(D25,Q1:R9,2,FALSE) -> 0 | N25: =M25*L25 -> 0 | O25: =IF(M25=0,0,L25*MAX(R2:R8)) -> 0
A27: Navigation
A29: =A25+1 -> 9 | B29: Users can easily access the site or application (e.g. the URL is predictable and is returned by search engines). | D29: Enter score | F29: =#REF!*#REF! -> #REF! | G29: =IF(#REF!>=0,10*#REF!,0) -> #REF! | K29: 2 | L29: =K29/K117 -> 0.4 | M29: =VLOOKUP(D29,Q1:R9,2,FALSE) -> 0 | N29: =M29*L29 -> 0 | O29: =IF(M29=0,0,L29*MAX(R2:R8)) -> 0
A31: =A29+1 -> 10 | B31: The navigational scheme (e.g. menu) is easy to find, intuitive and consistent. | D31: Enter score | F31: =#REF!*#REF! -> #REF! | G31: =IF(#REF!>=0,10*#REF!,0) -> #REF! | K31: 4 | L31: =K31/K117 -> 0.8 | M31: =VLOOKUP(D31,Q1:R9,2,FALSE) -> 0 | N31: =M31*L31 -> 0 | O31: =IF(M31=0,0,L31*MAX(R2:R8)) -> 0
A33: =A31+1 -> 11 | B33: The navigation has sufficient flexibility to allow users to navigate by their desired means (e.g. searching, browse by type, browse by name, most recent etc…). | D33: Enter score | K33: 3 | L33: =K33/K117 -> 0.6 | M33: =VLOOKUP(D33,Q1:R9,2,FALSE) -> 0 | N33: =M33*L33 -> 0 | O33: =IF(M33=0,0,L33*MAX(R2:R8)) -> 0
A35: =A33+1 -> 12 | B35: The site or application structure is clear, easily understood and addresses common user goals. | D35: Enter score | F35: =#REF!*#REF! -> #REF! | G35: =IF(#REF!>=0,10*#REF!,0) -> #REF! | K35: 5 | L35: =K35/K117 -> 1 | M35: =VLOOKUP(D35,Q1:R9,2,FALSE) -> 0 | N35: =M35*L35 -> 0 | O35: =IF(M35=0,0,L35*MAX(R2:R8)) -> 0
A37: =A35+1 -> 13 | B37: Links are clear, descriptive and and well labelled. | D37: Enter score | F37: =#REF!*#REF! -> #REF! | G37: =IF(#REF!>=0,10*#REF!,0) -> #REF! | K37: 3 | L37: =K37/K117 -> 0.6 | M37: =VLOOKUP(D37,Q1:R9,2,FALSE) -> 0 | N37: =M37*L37 -> 0 | O37: =IF(M37=0,0,L37*MAX(R2:R8)) -> 0
A39: =A37+1 -> 14 | B39: Browser standard functions (e.g. 'back', 'forward', 'bookmark') are supported. | D39: Enter score | F39: =#REF!*#REF! -> #REF! | G39: =IF(#REF!>=0,10*#REF!,0) -> #REF! | K39: 4 | L39: =K39/K117 -> 0.8 | M39: =VLOOKUP(D39,Q1:R9,2,FALSE) -> 0 | N39: =M39*L39 -> 0 | O39: =IF(M39=0,0,L39*MAX(R2:R8)) -> 0
A41: =A39+1 -> 15 | B41: The current location is clearly indicated (e.g. breadcrumb, highlighted menu item). | D41: Enter score | F41: =#REF!*#REF! -> #REF! | G41: =IF(#REF!>=0,10*#REF!,0) -> #REF! | K41: 2 | L41: =K41/K117 -> 0.4 | M41: =VLOOKUP(D41,Q1:R9,2,FALSE) -> 0 | N41: =M41*L41 -> 0 | O41: =IF(M41=0,0,L41*MAX(R2:R8)) -> 0
A43: =A41+1 -> 16 | B43: Users can easily get back to the homepage or a relevant start point. | D43: Enter score | F43: =#REF!*#REF! -> #REF! | G43: =IF(#REF!>=0,10*#REF!,0) -> #REF! | K43: 2 | L43: =K43/K117 -> 0.4 | M43: =VLOOKUP(D43,Q1:R9,2,FALSE) -> 0 | N43: =M43*L43 -> 0 | O43: =IF(M43=0,0,L43*MAX(R2:R8)) -> 0
A45: =A43+1 -> 17 | B45: A clear and well structure site map or index is provided (where necessary). | D45: Enter score | F45: =#REF!*#REF! -> #REF! | G45: =IF(#REF!>=0,10*#REF!,0) -> #REF! | K45: 1 | L45: =K45/K117 -> 0.2 | M45: =VLOOKUP(D45,Q1:R9,2,FALSE) -> 0 | N45: =M45*L45 -> 0 | O45: =IF(M45=0,0,L45*MAX(R2:R8)) -> 0
A47: Search
A49: =A45+1 -> 18 | B49: A consitent, easy to find and easy to use search function is available throughout (where desirable). | D49: Enter score | F49: =#REF!*#REF! -> #REF! | G49: =IF(#REF!>=0,10*#REF!,0) -> #REF! | K49: 4 | L49: =K49/K117 -> 0.8 | M49: =VLOOKUP(D49,Q1:R9,2,FALSE) -> 0 | N49: =M49*L49 -> 0 | O49: =IF(M49=0,0,L49*MAX(R2:R8)) -> 0
A51: =A49+1 -> 19 | B51: The search interface is appropriate to meet user goals (e.g. multi-parameter, prioritised results, filtering search results). | D51: Enter score | F51: =#REF!*#REF! -> #REF! | G51: =IF(#REF!>=0,10*#REF!,0) -> #REF! | K51: 4 | L51: =K51/K117 -> 0.8 | M51: =VLOOKUP(D51,Q1:R9,2,FALSE) -> 0 | N51: =M51*L51 -> 0 | O51: =IF(M51=0,0,L51*MAX(R2:R8)) -> 0
A53: =A51+1 -> 20 | B53: The search facility deals well with common searchs (e.g. showing most popular results), misspellings and abbreviations. | D53: Enter score | F53: =#REF!*#REF! -> #REF! | G53: =IF(#REF!>=0,10*#REF!,0) -> #REF! | K53: 2 | L53: =K53/K117 -> 0.4 | M53: =VLOOKUP(D53,Q1:R9,2,FALSE) -> 0 | N53: =M53*L53 -> 0 | O53: =IF(M53=0,0,L53*MAX(R2:R8)) -> 0
A55: =A53+1 -> 21 | B55: Search results are relevant, comprehensive, precise, and well displayed. | D55: Enter score | F55: =#REF!*#REF! -> #REF! | G55: =IF(#REF!>=0,10*#REF!,0) -> #REF! | K55: 4 | L55: =K55/K117 -> 0.8 | M55: =VLOOKUP(D55,Q1:R9,2,FALSE) -> 0 | N55: =M55*L55 -> 0 | O55: =IF(M55=0,0,L55*MAX(R2:R8)) -> 0
A57: Control & feedback
A59: =A55+1 -> 22 | B59: Prompt and appropriate feedback is given (e.g. following a successful or unsuccessful action). | D59: Enter score | F59: =#REF!*#REF! -> #REF! | G59: =IF(#REF!>=0,10*#REF!,0) -> #REF! | K59: 4 | L59: =K59/K117 -> 0.8 | M59: =VLOOKUP(D59,Q1:R9,2,FALSE) -> 0 | N59: =M59*L59 -> 0 | O59: =IF(M59=0,0,L59*MAX(R2:R8)) -> 0
A61: =A59+1 -> 23 | B61: Users can easily undo, go back and change or cancel actions; or are at least given the chance to confirm an action before commiting (e.g. before placing an order). | D61: Enter score | F61: =#REF!*#REF! -> #REF! | G61: =IF(#REF!>=0,10*#REF!,0) -> #REF! | K61: 3 | L61: =K61/K117 -> 0.6 | M61: =VLOOKUP(D61,Q1:R9,2,FALSE) -> 0 | N61: =M61*L61 -> 0 | O61: =IF(M61=0,0,L61*MAX(R2:R8)) -> 0
A63: =A61+1 -> 24 | B63: Users can easily give feedback (e.g. via email or an online feedback / contact us form). | D63: Enter score | F63: =#REF!*#REF! -> #REF! | G63: =IF(#REF!>=0,10*#REF!,0) -> #REF! | K63: 1 | L63: =K63/K117 -> 0.2 | M63: =VLOOKUP(D63,Q1:R9,2,FALSE) -> 0 | N63: =M63*L63 -> 0 | O63: =IF(M63=0,0,L63*MAX(R2:R8)) -> 0
A65: Forms
A67: =A63+1 -> 25 | B67: Complex forms and processes are broken up into readily understood steps and sections. Where a process is used a progress indicator is present with clear numbers or named stages. | D67: Enter score | F67: =#REF!*#REF! -> #REF! | G67: =IF(#REF!>=0,10*#REF!,0) -> #REF! | K67: 3 | L67: =K67/K117 -> 0.6 | M67: =VLOOKUP(D67,Q1:R9,2,FALSE) -> 0 | N67: =M67*L67 -> 0 | O67: =IF(M67=0,0,L67*MAX(R2:R8)) -> 0
A69: =A67+1 -> 26 | B69: A minimal amount of information is requested and where required justification is given for asking for information (e.g. date of birth, telephone number). | D69: Enter score | F69: =#REF!*#REF! -> #REF! | G69: =IF(#REF!>=0,10*#REF!,0) -> #REF! | K69: 2 | L69: =K69/K117 -> 0.4 | M69: =VLOOKUP(D69,Q1:R9,2,FALSE) -> 0 | N69: =M69*L69 -> 0 | O69: =IF(M69=0,0,L69*MAX(R2:R8)) -> 0
A71: =A69+1 -> 27 | B71: Required and optional form fields are clearly indicated. | D71: Enter score | F71: =#REF!*#REF! -> #REF! | G71: =IF(#REF!>=0,10*#REF!,0) -> #REF! | K71: 2 | L71: =K71/K117 -> 0.4 | M71: =VLOOKUP(D71,Q1:R9,2,FALSE) -> 0 | N71: =M71*L71 -> 0 | O71: =IF(M71=0,0,L71*MAX(R2:R8)) -> 0
A73: =A71+1 -> 28 | B73: Appropriate input fields (e.g. calendar for date selection, drop down for selection) are used and required formats are indicated. | D73: Enter score | F73: =#REF!*#REF! -> #REF! | G73: =IF(#REF!>=0,10*#REF!,0) -> #REF! | K73: 3 | L73: =K73/K117 -> 0.6 | M73: =VLOOKUP(D73,Q1:R9,2,FALSE) -> 0 | N73: =M73*L73 -> 0 | O73: =IF(M73=0,0,L73*MAX(R2:R8)) -> 0
...

Sheet Usability guidelines
A1: Usability guidelines
C2: Importance
A3: Features & functionality
A4: 1 | B4: Features and functionality meet common user goals and objectives Key and common user goals and objectives (e.g. carry out some transaction, find some information, carry out some research etc…) should have been identified and addressed. Ideally the site or application should allow users to meet all of their key goals and objectives. | C4: Very high
A5: =A4+1 -> 2 | B5: Features and functionality support users desired workflows The site or application should support or at least be compatible with the way that users wish to work. For example, users might want to be able to carry out bulk transactions or be able to save and return to their work. | C5: Very high
A6: =A5+1 -> 3 | B6: Frequently-used tasks are readily available (e.g. easily accessible from the homepage) and well supported For example short cuts and a login to retrieve details might be provided to speed up the completion of frequently carried out tasks. | C6: High
A7: =A6+1 -> 4 | B7: Users are adequately supported according to their level of expertise For example, novice users are given help and instructions and features are progressively disclosed (e.g. advanced features not being shown by default). | C7: Medium
A8: =A7+1 -> 5 | B8: Calls to action (e.g. register, add to basket, submit) are clear, well labelled and appear clickable Possible actions should always be clear and the primary call to action (i.e. the most common or desirable user action) should stand out on the page or screen. | C8: Medium
A10: Homepage / starting page
A11: =A8+1 -> 6 | B11: The Homepage / starting page provides a clear snapshot and overview of the content, features and functionality available For example, an introduction and overview of the site is provided together with section snapshots and example content. | C11: Medium
A12: =A11+1 -> 7 | B12: The homepage / starting page is effective in orienting and directing users to their desired information and tasks Users should be able to work out where they need to go to complete a given task (e.g. carry out some research, complete a transaction). | C12: High
A13: =A12+1 -> 8 | B13: The homepage / starting page layout is clear and uncluttered with sufficient 'white space' Users should be able to quickly scan the homepage and make sense of both the content available and of how the site is structured. | C13: Medium
A15: Navigation
A16: =A13+1 -> 9 | B16: Users can easily access the site or application For example, the URL is predictable and is returned by search engines. If a user attempts to find the site via a search engine, it should ideally be returned on the first page of search results for likely queries. | C16: Low
A17: =A16+1 -> 10 | B17: The navigational scheme is easy to find, intuitive and consistent Users should be able to very easily locate and use the navigational scheme (e.g. left hand menu, top menu, tabbed menu), and it should not be significantly different across the site or application (unless a decision has been made to specifically differentiate a given section or area). | C17: High
A18: =A17+1 -> 11 | B18: The navigation has sufficient flexibility to allow users to navigate by their desired means For example a user might want to be able to search for an item or browse by size, name or type. Although not all user preferences can or indeed should be addressed, the most useful and common navigational means should be supported. | C18: Medium
A19: =A18+1 -> 12 | B19: The site or application structure is clear, easily understood and addresses common user goals For example, gathering information, submitting data, carrying out research. Users should be able to work out where they need to go to carry out common user goals and be able to quickly gain an understanding of how the site or application is structured. | C19: Very high
A20: =A19+1 -> 13 | B20: Links are clear, descriptive and well labelled Links should be clearly 'clickable' (e.g. underlined or colourised) and it should be clear to users where any given link goes to. Non-descriptive links such as 'click here' should be avoided and any links going to an external website or opening a new window should be identified as such. | C20: Medium
A21: =A20+1 -> 14 | B21: Browser standard functions (e.g. 'back', 'forward', 'bookmark') are supported Users should be able to bookmark a page (or be presented with a URL to use) and go back and forth without breaking the site or losing any information they have entered. | C21: High
A22: =A21+1 -> 15 | B22: The current location is clearly indicated (e.g. breadcrumb, highlighted menu item) Users should always know where they are in the site or application. | C22: Low
A23: =A22+1 -> 16 | B23: Users can easily get back to the homepage or a relevant start point For example, a homepage link might be part of the breadcrumb or a home link might be available as part of the header. | C23: Low
A24: =A23+1 -> 17 | B24: A clear and well structure site map or index is provided (where necessary) The sitemap might be part of the header or footer and should ideally be available from every page on the site. | C24: Very low
A26: Search
A27: =A24+1 -> 18 | B27: A consistent, easy to find and easy to use search function is available throughout The search function (where required) should be directly available from most pages on the site or application and should be consistently positioned (e.g. top left, top right or top centre). | C27: High
A28: =A27+1 -> 19 | B28: The search interface is appropriate to meet user goals For example users are able to filter search results, an advanced search is available (if necessary) and common search conventions such as quotation marks (") and natural language searches are handled. | C28: High
A29: =A28+1 -> 20 | B29: The search facility deals well with common searches, misspellings and abbreviations Ideally synonyms (e.g. 'coat' should also match 'jacket') should mean that logical and appropriate search results are returned for common user queries. Popular search results (e.g. top matches) should also be identified for common queries. | C29: Low
A30: =A29+1 -> 21 | B30: Search results are relevant, comprehensive, precise, and well displayed It should be easy for users to see what has been returned, to work out why something has been returned and to determine how many results there are. | C30: High
A32: Control & feedback
A33: =A30+1 -> 22 | B33: Prompt and appropriate feedback is given For example, a confirmation message is shown following a successful transaction, input errors are promptly highlighted and it's made clear to users when a page has been updated. | C33: High
A34: =A33+1 -> 23 | B34: Users can easily undo, go back and change, or cancel actions If an action can not be undo then users should at least be given the chance to confirm an action before committing (e.g. before placing an order). For example, users can return to a step and change their options or dynamically change a value without having to start again. Where an action can't be undone (e.g. a deletion), this should be made clear to users. | C34: Medium
A35: =A34+1 -> 24 | B35: Users can easily give feedback For example, via email or an online feedback / contact us form. There should be an indication of how long users can expect to wait for a response if a query has been made. | C35: Very low
A37: Forms
A38: =A35+1 -> 25 | B38: Complex forms and processes are broken up into readily understood steps and sections For example, a checkout process might be broken up in to 'address', 'delivery options', 'payment' and 'confirmation'. Where a process is used a progress indicator is present with clear numbers or named stages. | C38: Medium
A39: =A38+1 -> 26 | B39: A minimal amount of information is requested and where necessary justification is given for asking for information For example a site might outline that a telephone number is required in case there is an issue with a transaction. Users shouldn't be asked for extraneous information and where possible information should be auto populated (e.g. postcode lookup, code lookup) to keep input to a minimum. | C39: Low
A40: =A39+1 -> 27 | B40: Required and optional form fields are clearly indicated (e.g. using text or '*') Where most fields are required the optional fields should be identified and when most fields are optional the required fields should be identified. | C40: Low
A41: =A40+1 -> 28 | B41: Appropriate input fields are used and required formats are indicated Appropriate input fields might include calendar for date selection, drop downs for selection and radio button for small selections. Text might be used to indicate the required format or an example might be provided. Field lengths should correspond to the expected input so for example an email input field should be long, where as an initials input field should be very short. | C41: Medium
A42: =A41+1 -> 29 | B42: Help and instructions (e.g. examples, information required) are provided where necessary Where input is non trivial or is likely to require some explanation this should be provided. Where a-lot of explanation is necessary a link to a page outlining what is required should be provided. | C42: Medium
A44: Errors
A45: =A42+1 -> 30 | B45: Errors are clear, easily identified and appear in appropriate locations Errors should be immediately apparent to users and ideally be located close to the offending input or function (e.g. adjacent to an input entry field). Inputs causing an error should be highlighted, together with an explanation for the error. | C45: High
A46: =A45+1 -> 31 | B46: Error messages are concise, written in easy to understand language and describe what's occurred and what action is necessary Errors should avoid using very technical terms or jargon and should be written from the user's perspective. | C46: Medium
...

Sheet Rating ranges
A1: Rating below | B1: Rating | C1: Rating ranges
A2: 0 | B2: =""
A3: 1 | B3: Very Poor | C3: less than | D3: =A4 -> 29
A4: 29 | B4: Poor | C4: between | D4: =A4 -> 29 | E4: and | F4: =A5 -> 49
A5: 49 | B5: Moderate | C5: between | D5: =A5 -> 49 | E5: and | F5: =A6 -> 69
A6: 69 | B6: Good | C6: between | D6: =A6 -> 69 | E6: and | F6: =A7 -> 89
A7: 89 | B7: Excellent | C7: more than | D7: =A7 -> 89
